<?xml version="1.0"?>
<robot xmlns:xacro="http://www.ros.org/wiki/xacro" name="rosni_robot">
  <xacro:macro name="left_wheel" params="name parent *origin">
    <link name="${name}_link" type="wheel">
      <inertial>
      <origin xyz="0 0 0" />
      <mass value="2.8498940e-02" />
      <inertia ixx="1.1175580e-05" ixy="-4.2369783e-11" ixz="-5.9381719e-09"
               iyy="1.1192413e-05" iyz="-1.4400107e-11"
               izz="2.0712558e-05" />
      </inertial>
      <visual>
        <origin xyz="-0.0425 -0.0425 0" rpy="0 0 0"/>
				<geometry>
        	<mesh filename="file://$(find rosni2_description)/meshes/left_wheel.stl" scale="0.001 0.001 0.001"/>
      	</geometry>
        <material name="red">
          <color rgba="0.7 0 0 1"/>
        </material>
      </visual>
      <collision>
        <origin xyz="0. 0. 0.01" rpy="0 0 0"/>
				<geometry>
           <cylinder radius="0.0425" length="0.01"/>
        </geometry>
      </collision>
    </link>
    <joint name="${name}_joint" type="continuous">
      <xacro:insert_block name="origin"/>
      <axis xyz="0 0 1"/>
      <parent link="${parent}_link"/>
      <child link="${name}_link"/>
    </joint>
  </xacro:macro>
</robot>